Here's a detailed overview of Python's exception handling, based on the provided transcript:

## Python Exception Handling: Graceful Error Management

Exception handling in Python is a crucial mechanism that allows your program to deal with errors gracefully during execution, preventing it from crashing and enabling it to take corrective actions. Instead of abruptly stopping, you can provide informative feedback to the user or perform necessary cleanup operations.

-----

### **1. Errors vs. Exceptions**

  * **Errors:** Fatal problems that prevent the program from running, often due to syntactical issues or fundamental flaws that cannot be recovered from during runtime (e.g., `SyntaxError`).

  * **Exceptions:** Events that disrupt the normal flow of a program during its execution. They occur when an error is encountered *during* program execution but can be caught and handled programmatically, allowing the program to continue or exit gracefully.

    **Common Types of Exceptions:**

      * `NameError`: When a variable or function name is not found.
      * `ZeroDivisionError`: When division by zero occurs.
      * `FileNotFoundError`: When a file cannot be found.
      * `ValueError`: When an operation receives an argument that has the right type but an inappropriate value.
      * `TypeError`: When an operation is applied to an object of an inappropriate type.

-----

### **2. The `try` and `except` Blocks**

The core of exception handling involves the `try` and `except` blocks.

  * **`try` block:**

      * Contains the code that might potentially raise an exception.
      * If an exception occurs within the `try` block, the rest of the code in the `try` block is skipped, and Python immediately looks for a matching `except` block.
      * If no exception occurs, the `except` block is skipped.

  * **`except` block:**

      * Catches and handles specific exceptions that occur in the corresponding `try` block.
      * You can specify the type of exception you want to catch.

**Syntax:**

```python
try:
    # Code that might raise an exception
except ExceptionType:
    # Code to handle the exception
```

**Example 1: Handling `NameError`**

```python
# Without exception handling (will crash)
# a = b
# print(a)
# Output: NameError: name 'b' is not defined

# With try-except
try:
    a = b  # This line will raise a NameError
except NameError:
    print("Error: The variable 'b' has not been assigned or defined.")
# Output: Error: The variable 'b' has not been assigned or defined.
```

**Example 2: Handling `ZeroDivisionError`**

```python
try:
    result = 10 / 0  # This will raise a ZeroDivisionError
except ZeroDivisionError:
    print("Error: Cannot divide by zero. Please enter a denominator greater than zero.")
# Output: Error: Cannot divide by zero. Please enter a denominator greater than zero.
```

**Accessing the Exception Message:**

You can catch the exception and assign it to a variable (using `as alias`) to access its default error message.

```python
try:
    a = b
except NameError as x: # 'x' is an alias for the exception object
    print(f"Caught NameError: {x}")
    print("The variable has not been assigned.")
# Output:
# Caught NameError: name 'b' is not defined
# The variable has not been assigned.
```

-----

### **3. Handling Multiple Exceptions**

You can have multiple `except` blocks to handle different types of exceptions, or a single `except` block to catch a tuple of exceptions.

**Catching Specific Exceptions:**

Python will try to match the raised exception with the first matching `except` block. It's best practice to list more specific exceptions first, followed by more general ones.

```python
try:
    num = int(input("Enter a number: "))
    result = 10 / num
except ValueError:
    print("Error: That's not a valid number. Please enter an integer.")
except ZeroDivisionError:
    print("Error: You can't divide by zero.")
except Exception as e: # Generic exception, catches anything else
    print(f"An unexpected error occurred: {e}")
```

**Demonstration:**

  * **Input: `0`**
      * Output: `Error: You can't divide by zero.` (Caught by `ZeroDivisionError`)
  * **Input: `abc`**
      * Output: `Error: That's not a valid number. Please enter an integer.` (Caught by `ValueError`)
  * **Input: `5`**
      * Output: (No exception, code proceeds)

**The `Exception` Base Class:**

  * `Exception` is the base class for most standard Python exceptions.
  * An `except Exception as e:` block will catch *any* exception that derives from `Exception`.
  * It should always be placed **last** in a sequence of `except` blocks to ensure more specific exceptions are handled first.

-----

### **4. The `else` Block**

The `else` block (in `try...except...else`) is executed *only if no exception occurs* in the `try` block.

  * **Purpose:** To contain code that should run only when the `try` block executes successfully without raising any exceptions.

**Syntax:**

```python
try:
    # Code that might raise an exception
except ExceptionType:
    # Code to handle the exception
else:
    # Code to execute if NO exception occurs in the try block
```

**Example:**

```python
try:
    num = int(input("Enter a number: "))
    result = 10 / num
except ValueError:
    print("Error: Invalid input. Please enter an integer.")
except ZeroDivisionError:
    print("Error: Cannot divide by zero.")
else:
    # This block runs ONLY if no exception occurred in the try block
    print(f"Successfully calculated! Result: {result}")
```

**Demonstration:**

  * **Input: `5`**
      * Output: `Successfully calculated! Result: 2.0` (Else block executed)
  * **Input: `0`**
      * Output: `Error: Cannot divide by zero.` (Except block executed, Else block skipped)

-----

### **5. The `finally` Block**

The `finally` block is guaranteed to be executed, regardless of whether an exception occurred in the `try` block or not.

  * **Purpose:** To perform cleanup actions (e.g., closing files, releasing resources, closing database connections) that must happen regardless of the outcome of the `try` block.

**Syntax:**

```python
try:
    # Code that might raise an exception
except ExceptionType:
    # Code to handle the exception
else:
    # Code to execute if NO exception occurs
finally:
    # Code that MUST execute, always
```

**Example:**

```python
try:
    num = int(input("Enter a number: "))
    result = 10 / num
except ValueError:
    print("Error: Invalid input. Please enter an integer.")
except ZeroDivisionError:
    print("Error: Cannot divide by zero.")
else:
    print(f"Result: {result}")
finally:
    print("Execution complete. This block always runs.")
```

**Demonstration:**

  * **Input: `5`**
      * Output:
        ```
        Result: 2.0
        Execution complete. This block always runs.
        ```
    (No exception, `else` runs, then `finally` runs)
  * **Input: `0`**
      * Output:
        ```
        Error: Cannot divide by zero.
        Execution complete. This block always runs.
        ```
    (Exception caught by `except`, `else` skipped, `finally` still runs)

**Real-world Use Case for `finally`:**
Imagine connecting to a database. If an error occurs during your database operations, you still need to close the database connection to free up resources. The `finally` block is perfect for this:

```python
db_connection = None
try:
    # db_connection = connect_to_database() # Hypothetical connection
    # perform_database_operations(db_connection)
    print("Database operations performed.")
    # Simulate an error
    # raise ValueError("Simulating an error in DB operations")
except Exception as e:
    print(f"An error occurred: {e}")
finally:
    if db_connection: # Check if connection was successfully established
        # db_connection.close() # Hypothetical close connection
        print("Database connection closed.")
    else:
        print("No database connection was active to close.")
```

-----

### **6. File Handling with Exception Handling**

Combining file operations with `try-except-finally` is a common and robust pattern. This ensures files are properly closed even if errors occur during reading or writing.

**Example: Reading a file with `finally` to ensure closure**

```python
file = None # Initialize file to None
try:
    # Attempt to open a file that might not exist
    file = open("non_existent_file.txt", "r")
    content = file.read()
    print("File content:", content)
except FileNotFoundError:
    print("Error: The file does not exist.")
except Exception as e:
    print(f"An unexpected error occurred: {e}")
finally:
    # This block will always run, ensuring the file is closed if it was opened
    if file: # Check if the file object was successfully assigned (i.e., not None)
        file.close()
        print("File connection closed in finally block.")
    else:
        print("File was not opened, so no need to close.")

# Example with a file that exists
# try:
#     file = open("Example.txt", "r") # Assuming Example.txt exists
#     content = file.read()
#     print("File content:", content)
# except FileNotFoundError:
#     print("Error: The file does not exist.")
# finally:
#     if file:
#         file.close()
#         print("File closed in finally block.")

```

*Note: While `finally` ensures closure, the `with open(...) as file:` statement is generally preferred for file handling as it's more concise and automatically handles closure, making `finally` less common for *just* file closing.*

Exception handling is fundamental for writing reliable and user-friendly Python applications. It allows you to anticipate potential problems and manage them gracefully, improving the overall robustness of your code.